I'm sorry, but an uncaught exception occurred.

While running game code:
  File "game/script.rpy", line 324, in script
    mi "Well, well... hehehe... After you, Kei-chan..."
Exception: Sayer 'mi' is not defined.

-- Full Traceback ------------------------------------------------------------

Full traceback:
  File "game/script.rpy", line 324, in script
    mi "Well, well... hehehe... After you, Kei-chan..."
  File "renpy/ast.py", line 680, in execute
    who = eval_who(self.who, self.who_fast)
  File "renpy/ast.py", line 574, in eval_who
    raise Exception("Sayer '%s' is not defined." % who)
Exception: Sayer 'mi' is not defined.

Windows-10-10.0.19041
Ren'Py 7.4.4.1439
Higurashi Gou 
Fri May 28 09:11:48 2021
