I'm sorry, but an uncaught exception occurred.

While running game code:
  File "game/script.rpy", line 921, in script
    mi "I guess that's it for today... Kei-chan, do you want to walk home together?"
Exception: Sayer 'mi' is not defined.

-- Full Traceback ------------------------------------------------------------

Full traceback:
  File "game/script.rpy", line 921, in script
    mi "I guess that's it for today... Kei-chan, do you want to walk home together?"
  File "renpy/ast.py", line 680, in execute
    who = eval_who(self.who, self.who_fast)
  File "renpy/ast.py", line 574, in eval_who
    raise Exception("Sayer '%s' is not defined." % who)
Exception: Sayer 'mi' is not defined.

Windows-10-10.0.19041
Ren'Py 7.4.6.1668
Higurashi Gou 
Tue Jun  8 18:36:08 2021
